<?xml version="1.0" encoding="UTF-8"?>
<testng-results ignored="0" total="2" passed="2" failed="0" skipped="0">
  <reporter-output>
  </reporter-output>
  <suite started-at="2024-06-11T07:01:22 EDT" name="Default suite" finished-at="2024-06-11T07:01:22 EDT" duration-ms="59">
    <groups>
    </groups>
    <test started-at="2024-06-11T07:01:22 EDT" name="Default test" finished-at="2024-06-11T07:01:22 EDT" duration-ms="59">
      <class name="testNgExample.ExpectedExceptionAttribute">
        <test-method signature="testMethod()[pri:0, instance:testNgExample.ExpectedExceptionAttribute@647fd8ce]" started-at="2024-06-11T07:01:22 EDT" name="testMethod" finished-at="2024-06-11T07:01:22 EDT" duration-ms="13" status="PASS">
          <exception class="java.lang.ArithmeticException">
            <message>
              <![CDATA[/ by zero]]>
            </message>
            <full-stacktrace>
              <![CDATA[java.lang.ArithmeticException: / by zero
at testNgExample.ExpectedExceptionAttribute.testMethod(ExpectedExceptionAttribute.java:9)
at java.base/jdk.internal.reflect.NativeMethodAccessorImpl.invoke0(Native Method)
at java.base/jdk.internal.reflect.NativeMethodAccessorImpl.invoke(NativeMethodAccessorImpl.java:77)
at java.base/jdk.internal.reflect.DelegatingMethodAccessorImpl.invoke(DelegatingMethodAccessorImpl.java:43)
at java.base/java.lang.reflect.Method.invoke(Method.java:568)
at org.testng.internal.MethodInvocationHelper.invokeMethod(MethodInvocationHelper.java:133)
at org.testng.internal.TestInvoker.invokeMethod(TestInvoker.java:598)
at org.testng.internal.TestInvoker.invokeTestMethod(TestInvoker.java:173)
at org.testng.internal.MethodRunner.runInSequence(MethodRunner.java:46)
at org.testng.internal.TestInvoker$MethodInvocationAgent.invoke(TestInvoker.java:824)
at org.testng.internal.TestInvoker.invokeTestMethods(TestInvoker.java:146)
at org.testng.internal.TestMethodWorker.invokeTestMethods(TestMethodWorker.java:146)
at org.testng.internal.TestMethodWorker.run(TestMethodWorker.java:128)
at java.base/java.util.ArrayList.forEach(ArrayList.java:1511)
at org.testng.TestRunner.privateRun(TestRunner.java:794)
at org.testng.TestRunner.run(TestRunner.java:596)
at org.testng.SuiteRunner.runTest(SuiteRunner.java:377)
at org.testng.SuiteRunner.runSequentially(SuiteRunner.java:371)
at org.testng.SuiteRunner.privateRun(SuiteRunner.java:332)
at org.testng.SuiteRunner.run(SuiteRunner.java:276)
at org.testng.SuiteRunnerWorker.runSuite(SuiteRunnerWorker.java:53)
at org.testng.SuiteRunnerWorker.run(SuiteRunnerWorker.java:96)
at org.testng.TestNG.runSuitesSequentially(TestNG.java:1212)
at org.testng.TestNG.runSuitesLocally(TestNG.java:1134)
at org.testng.TestNG.runSuites(TestNG.java:1063)
at org.testng.TestNG.run(TestNG.java:1031)
at org.testng.remote.AbstractRemoteTestNG.run(AbstractRemoteTestNG.java:115)
at org.testng.remote.RemoteTestNG.initAndRun(RemoteTestNG.java:251)
at org.testng.remote.RemoteTestNG.main(RemoteTestNG.java:77)
]]>
            </full-stacktrace>
          </exception> <!-- java.lang.ArithmeticException -->
          <reporter-output>
          </reporter-output>
        </test-method> <!-- testMethod -->
        <test-method signature="testMethod2()[pri:0, instance:testNgExample.ExpectedExceptionAttribute@647fd8ce]" started-at="2024-06-11T07:01:22 EDT" name="testMethod2" finished-at="2024-06-11T07:01:22 EDT" duration-ms="2" status="PASS">
          <reporter-output>
          </reporter-output>
        </test-method> <!-- testMethod2 -->
      </class> <!-- testNgExample.ExpectedExceptionAttribute -->
    </test> <!-- Default test -->
  </suite> <!-- Default suite -->
</testng-results>
